<?xml version="1.0" ?>
<robot name="bbl" xmlns:xacro="http://www.ros.org/wiki/xacro">

<xacro:include filename="$(find bbl_description)/urdf/materials.xacro" />
<xacro:include filename="$(find bbl_description)/urdf/bbl.trans" />
<xacro:include filename="$(find bbl_description)/urdf/bbl.gazebo" />
<link name="base_link">
  <inertial>
    <origin xyz="7.05749757971293e-05 0.0 0.027523524991931014" rpy="0 0 0"/>
    <mass value="0.1"/>
    <inertia ixx="0.001738" iyy="0.001745" izz="0.003277" ixy="0.0" iyz="0.0" ixz="-2e-06"/>
  </inertial>
  <visual>
    <origin xyz="0 0 0" rpy="0 0 0"/>
    <geometry>
      <mesh filename="package://bbl_description/meshes/base_link.stl" scale="0.001 0.001 0.001"/>
    </geometry>
    <material name="silver"/>
  </visual>
  <collision>
    <origin xyz="0 0 0" rpy="0 0 0"/>
    <geometry>
      <mesh filename="package://bbl_description/meshes/base_link.stl" scale="0.001 0.001 0.001"/>
    </geometry>
  </collision>
</link>

<link name="right_wheel_1">
  <inertial>
    <origin xyz="0.0 -0.004868749381211707 0.0" rpy="0 0 0"/>
    <mass value="0.053725503838161597"/>
    <inertia ixx="4e-06" iyy="6e-06" izz="3e-06" ixy="0.0" iyz="0.0" ixz="0.0"/>
  </inertial>
  <visual>
    <origin xyz="0.05 0.05 -0.015" rpy="0 0 0"/>
    <geometry>
      <mesh filename="package://bbl_description/meshes/right_wheel_1.stl" scale="0.001 0.001 0.001"/>
    </geometry>
    <material name="red"/>
  </visual>
  <collision>
    <origin xyz="0.05 0.05 -0.015" rpy="0 0 0"/>
    <geometry>
      <mesh filename="package://bbl_description/meshes/right_wheel_1.stl" scale="0.001 0.001 0.001"/>
    </geometry>
  </collision>
</link>

<link name="left_wheel_1">
  <inertial>
    <origin xyz="0.0 0.004868749381211693 -1.734723475976807e-18" rpy="0 0 0"/>
    <mass value="0.0537255038381616"/>
    <inertia ixx="4e-06" iyy="6e-06" izz="3e-06" ixy="-0.0" iyz="0.0" ixz="0.0"/>
  </inertial>
  <visual>
    <origin xyz="0.05 -0.05 -0.015" rpy="0 0 0"/>
    <geometry>
      <mesh filename="package://bbl_description/meshes/left_wheel_1.stl" scale="0.001 0.001 0.001"/>
    </geometry>
    <material name="blue"/>
  </visual>
  <collision>
    <origin xyz="0.05 -0.05 -0.015" rpy="0 0 0"/>
    <geometry>
      <mesh filename="package://bbl_description/meshes/left_wheel_1.stl" scale="0.001 0.001 0.001"/>
    </geometry>
  </collision>
</link>

<link name="caster_1">
  <inertial>
    <origin xyz="0.04499999999921576 -8.501987667641499e-19 -0.006718750000000044" rpy="0 0 0"/>
    <mass value="0.008220500776893026"/>
    <inertia ixx="0.0" iyy="0.0" izz="0.0" ixy="-0.0" iyz="0.0" ixz="0.0"/>
  </inertial>
  <visual>
    <origin xyz="-0.0 -0.0 -0.015" rpy="0 0 0"/>
    <geometry>
      <mesh filename="package://bbl_description/meshes/caster_1.stl" scale="0.001 0.001 0.001"/>
    </geometry>
    <material name="white"/>
  </visual>
  <collision>
    <origin xyz="-0.0 -0.0 -0.015" rpy="0 0 0"/>
    <geometry>
      <mesh filename="package://bbl_description/meshes/caster_1.stl" scale="0.001 0.001 0.001"/>
    </geometry>
  </collision>
</link>

<link name="lidar_1">
  <inertial>
    <origin xyz="-5.228456556594097e-13 0.0 0.0010000000000000078" rpy="0 0 0"/>
    <mass value="0.0012330751165340475"/>
    <inertia ixx="0.0" iyy="0.0" izz="0.0" ixy="0.0" iyz="0.0" ixz="-0.0"/>
  </inertial>
  <visual>
    <origin xyz="-0.045 -0.0 -0.045" rpy="0 0 0"/>
    <geometry>
      <mesh filename="package://bbl_description/meshes/lidar_1.stl" scale="0.001 0.001 0.001"/>
    </geometry>
    <material name="black"/>
  </visual>
  <collision>
    <origin xyz="-0.045 -0.0 -0.045" rpy="0 0 0"/>
    <geometry>
      <mesh filename="package://bbl_description/meshes/lidar_1.stl" scale="0.001 0.001 0.001"/>
    </geometry>
  </collision>
</link>

<joint name="right_wheel_joint" type="continuous">
  <origin xyz="-0.05 -0.05 0.015" rpy="0 0 0"/>
  <parent link="base_link"/>
  <child link="right_wheel_1"/>
  <axis xyz="0.0 1.0 0.0"/>
</joint>

<joint name="left_wheel_joint" type="continuous">
  <origin xyz="-0.05 0.05 0.015" rpy="0 0 0"/>
  <parent link="base_link"/>
  <child link="left_wheel_1"/>
  <axis xyz="0.0 1.0 0.0"/>
</joint>

<joint name="caster_joint" type="fixed">
  <origin xyz="0.0 0.0 0.015" rpy="0 0 0"/>
  <parent link="base_link"/>
  <child link="caster_1"/>
</joint>

<joint name="lidar_joint" type="fixed">
  <origin xyz="0.045 0.0 0.045" rpy="0 0 0"/>
  <parent link="base_link"/>
  <child link="lidar_1"/>
</joint>

</robot>
